Workbook
Name cop: #REF!

Sheet data
A1: Customer_ID | B1: Full_Name | C1: First_Name | D1: Last_Name | E1: Age | F1: Age_bin | G1: Gender | H1: City | I1: Email | J1: Email_from _domain | K1: Address | L1: Order_ID | M1: Order_Date | N1: Order_Time | O1: Product_ID | P1: Price | Q1: Quantity | R1: Coupon_Code | S1: COUPON % | T1: Estimatd_Days_Deliver | U1: Delivery_Status | V1: Delivery_Charge | W1: Days to Deliver | X1: Delivery_Date | Y1: Year | Z1: Month | AA1: Delivery_Time | AB1: Amount_del_charges(Final) | AC1: TOTAL DISCOUNT | AD1: Revnue(Sales-disc) | AE1: SALES
A2: CID186 | B2: =CONCATENATE(C2," ", D2," ") -> Anne Oconnell | C2: Anne | D2: Oconnell | E2: 37 | F2: =IF(E2<=25,"0-25",IF(E2<=35,"26-35",IF(E2<=45,"36-45",">45"))) -> 36-45 | G2: Male | H2: Phoenix | I2: anne.oconnell@outlook.com | J2: =MID(I2,FIND("@",I2)+1,100) -> outlook.com | K2: 2850 Matthew Ford, North Yolandachester, FL 67488 | L2: OID2497 | M2: 45358 | N2: 18:16:33 | O2: PID022 | P2: 308.88 | Q2: 5 | R2: FLAT8 | S2: 8 | T2: 4 | U2: =IF(W2<T2,"Before_time",IF(W2>T2,"Late_Delivery","On_time")) -> Before_time | V2: 60 | W2: =DATEDIF(M2,X2,"D") -> 3 | X2: 45361 | Y2: =YEAR(Table2[[#This Row],[Delivery_Date]]) -> 2024 | Z2: =TEXT(X2,"mmm") -> Mar | AA2: 08:51:31 | AB2: =AD2+V2 -> 1480.848 | AC2: =Table2[[#This Row],[Price]]*Table2[[#This Row],[Quantity]]*Table2[[#This Row],[COUPON %]]/100 -> 123.552 | AD2: =P2*Q2*(1-S2/100) -> 1420.848 | AE2: =P2*Q2 -> 1544.4
A3: CID150 | B3: =CONCATENATE(C3," ", D3," ") -> Anthony Thomas | C3: Anthony | D3: Thomas | E3: 53 | F3: =IF(E3<=25,"0-25",IF(E3<=35,"26-35",IF(E3<=45,"36-45",">45"))) -> >45 | G3: Female | H3: Houston | I3: anthony.thomas@rediffmail.com | J3: =MID(I3,FIND("@",I3)+1,100) -> rediffmail.com | K3: 931 Christopher Ways Suite 833, North Michelle, IN 53484 | L3: OID7056 | M3: 45378 | N3: 01:46:33 | O3: PID015 | P3: 166.28 | Q3: 4 | R3: FLAT8 | S3: 8 | T3: 7 | U3: =IF(W3<T3,"Before_time",IF(W3>T3,"Late_Delivery","On_time")) -> Before_time | V3: 66 | W3: =DATEDIF(M3,X3,"D") -> 3 | X3: 45381 | Y3: =YEAR(Table2[[#This Row],[Delivery_Date]]) -> 2024 | Z3: =TEXT(X3,"mmm") -> Mar | AA3: 18:46:26 | AB3: =AD3+V3 -> 677.9104 | AC3: =Table2[[#This Row],[Price]]*Table2[[#This Row],[Quantity]]*Table2[[#This Row],[COUPON %]]/100 -> 53.2096 | AD3: =P3*Q3*(1-S3/100) -> 611.9104 | AE3: =P3*Q3 -> 665.12
A4: CID115 | B4: =CONCATENATE(C4," ", D4," ") -> Karl Gallagher | C4: Karl | D4: Gallagher | E4: 60 | F4: =IF(E4<=25,"0-25",IF(E4<=35,"26-35",IF(E4<=45,"36-45",">45"))) -> >45 | G4: Other | H4: Phoenix | I4: karl.gallagher@rediffmail.com | J4: =MID(I4,FIND("@",I4)+1,100) -> rediffmail.com | K4: 5016 Snow Mountains Apt. 063, New Seanport, WY 41492 | L4: OID7502 | M4: 45342 | N4: 07:31:36 | O4: PID023 | P4: 202.54 | Q4: 1 | R4: FLAT15 | S4: 15 | T4: 3 | U4: =IF(W4<T4,"Before_time",IF(W4>T4,"Late_Delivery","On_time")) -> Before_time | V4: 47 | W4: =DATEDIF(M4,X4,"D") -> 2 | X4: 45344 | Y4: =YEAR(Table2[[#This Row],[Delivery_Date]]) -> 2024 | Z4: =TEXT(X4,"mmm") -> Feb | AA4: 14:29:50 | AB4: =AD4+V4 -> 219.159 | AC4: =Table2[[#This Row],[Price]]*Table2[[#This Row],[Quantity]]*Table2[[#This Row],[COUPON %]]/100 -> 30.381 | AD4: =P4*Q4*(1-S4/100) -> 172.159 | AE4: =P4*Q4 -> 202.54
A5: CID115 | B5: =CONCATENATE(C5," ", D5," ") -> Karl Gallagher | C5: Karl | D5: Gallagher | E5: 60 | F5: =IF(E5<=25,"0-25",IF(E5<=35,"26-35",IF(E5<=45,"36-45",">45"))) -> >45 | G5: Other | H5: Phoenix | I5: karl.gallagher@rediffmail.com | J5: =MID(I5,FIND("@",I5)+1,100) -> rediffmail.com | K5: 5016 Snow Mountains Apt. 063, New Seanport, WY 41492 | L5: OID7077 | M5: 45426 | N5: 18:29:21 | O5: PID031 | P5: 405 | Q5: 5 | R5: DEL0 | S5: 0 | T5: 6 | U5: =IF(W5<T5,"Before_time",IF(W5>T5,"Late_Delivery","On_time")) -> Before_time | V5: 47 | W5: =DATEDIF(M5,X5,"D") -> 4 | X5: 45430 | Y5: =YEAR(Table2[[#This Row],[Delivery_Date]]) -> 2024 | Z5: =TEXT(X5,"mmm") -> May | AA5: 07:00:32 | AB5: =AD5+V5 -> 2072 | AC5: =Table2[[#This Row],[Price]]*Table2[[#This Row],[Quantity]]*Table2[[#This Row],[COUPON %]]/100 -> 0 | AD5: =P5*Q5*(1-S5/100) -> 2025 | AE5: =P5*Q5 -> 2025
A6: CID149 | B6: =CONCATENATE(C6," ", D6," ") -> Angela Horne | C6: Angela | D6: Horne | E6: 49 | F6: =IF(E6<=25,"0-25",IF(E6<=35,"26-35",IF(E6<=45,"36-45",">45"))) -> >45 | G6: Other | H6: Phoenix | I6: angela.horne@outlook.com | J6: =MID(I6,FIND("@",I6)+1,100) -> outlook.com | K6: USNV Mueller, FPO AP 54648 | L6: OID2793 | M6: 45391 | N6: 03:23:21 | O6: PID015 | P6: 166.28 | Q6: 1 | R6: FLAT8 | S6: 8 | T6: 2 | U6: =IF(W6<T6,"Before_time",IF(W6>T6,"Late_Delivery","On_time")) -> Late_Delivery | V6: 54 | W6: =DATEDIF(M6,X6,"D") -> 4 | X6: 45395 | Y6: =YEAR(Table2[[#This Row],[Delivery_Date]]) -> 2024 | Z6: =TEXT(X6,"mmm") -> Apr | AA6: 22:10:58 | AB6: =AD6+V6 -> 206.9776 | AC6: =Table2[[#This Row],[Price]]*Table2[[#This Row],[Quantity]]*Table2[[#This Row],[COUPON %]]/100 -> 13.3024 | AD6: =P6*Q6*(1-S6/100) -> 152.9776 | AE6: =P6*Q6 -> 166.28
A7: CID159 | B7: =CONCATENATE(C7," ", D7," ") -> Christine West | C7: Christine | D7: West | E7: 53 | F7: =IF(E7<=25,"0-25",IF(E7<=35,"26-35",IF(E7<=45,"36-45",">45"))) -> >45 | G7: Other | H7: New York | I7: christine.west@gmail.com | J7: =MID(I7,FIND("@",I7)+1,100) -> gmail.com | K7: Unit 1433 Box 0246, DPO AP 94952 | L7: OID1483 | M7: 45543 | N7: 16:55:06 | O7: PID043 | P7: 330.11 | Q7: 4 | R7: FLAT15 | S7: 15 | T7: 6 | U7: =IF(W7<T7,"Before_time",IF(W7>T7,"Late_Delivery","On_time")) -> Before_time | V7: 39 | W7: =DATEDIF(M7,X7,"D") -> 4 | X7: 45547 | Y7: =YEAR(Table2[[#This Row],[Delivery_Date]]) -> 2024 | Z7: =TEXT(X7,"mmm") -> Sep | AA7: 11:25:50 | AB7: =AD7+V7 -> 1161.374 | AC7: =Table2[[#This Row],[Price]]*Table2[[#This Row],[Quantity]]*Table2[[#This Row],[COUPON %]]/100 -> 198.066 | AD7: =P7*Q7*(1-S7/100) -> 1122.374 | AE7: =P7*Q7 -> 1320.44
A8: CID115 | B8: =CONCATENATE(C8," ", D8," ") -> Karl Gallagher | C8: Karl | D8: Gallagher | E8: 60 | F8: =IF(E8<=25,"0-25",IF(E8<=35,"26-35",IF(E8<=45,"36-45",">45"))) -> >45 | G8: Other | H8: Phoenix | I8: karl.gallagher@rediffmail.com | J8: =MID(I8,FIND("@",I8)+1,100) -> rediffmail.com | K8: 5016 Snow Mountains Apt. 063, New Seanport, WY 41492 | L8: OID4105 | M8: 45662 | N8: 09:47:21 | O8: PID022 | P8: 308.88 | Q8: 5 | R8: FLAT20 | S8: 20 | T8: 5 | U8: =IF(W8<T8,"Before_time",IF(W8>T8,"Late_Delivery","On_time")) -> Before_time | V8: 47 | W8: =DATEDIF(M8,X8,"D") -> 3 | X8: 45665 | Y8: =YEAR(Table2[[#This Row],[Delivery_Date]]) -> 2025 | Z8: =TEXT(X8,"mmm") -> Jan | AA8: 20:10:50 | AB8: =AD8+V8 -> 1282.52 | AC8: =Table2[[#This Row],[Price]]*Table2[[#This Row],[Quantity]]*Table2[[#This Row],[COUPON %]]/100 -> 308.88 | AD8: =P8*Q8*(1-S8/100) -> 1235.52 | AE8: =P8*Q8 -> 1544.4
A9: CID198 | B9: =CONCATENATE(C9," ", D9," ") -> David Delacruz | C9: David | D9: Delacruz | E9: 26 | F9: =IF(E9<=25,"0-25",IF(E9<=35,"26-35",IF(E9<=45,"36-45",">45"))) -> 26-35 | G9: Female | H9: Los Angeles | I9: david.delacruz@rediffmail.com | J9: =MID(I9,FIND("@",I9)+1,100) -> rediffmail.com | K9: USNS Ray, FPO AE 20238 | L9: OID4372 | M9: 45459 | N9: 19:27:45 | O9: PID046 | P9: 363.64 | Q9: 3 | R9: FLAT10 | S9: 10 | T9: 2 | U9: =IF(W9<T9,"Before_time",IF(W9>T9,"Late_Delivery","On_time")) -> Late_Delivery | V9: 70 | W9: =DATEDIF(M9,X9,"D") -> 5 | X9: 45464 | Y9: =YEAR(Table2[[#This Row],[Delivery_Date]]) -> 2024 | Z9: =TEXT(X9,"mmm") -> Jun | AA9: 12:36:32 | AB9: =AD9+V9 -> 1051.828 | AC9: =Table2[[#This Row],[Price]]*Table2[[#This Row],[Quantity]]*Table2[[#This Row],[COUPON %]]/100 -> 109.092 | AD9: =P9*Q9*(1-S9/100) -> 981.828 | AE9: =P9*Q9 -> 1090.92
A10: CID152 | B10: =CONCATENATE(C10," ", D10," ") -> Marcus Valenzuela | C10: Marcus | D10: Valenzuela | E10: 39 | F10: =IF(E10<=25,"0-25",IF(E10<=35,"26-35",IF(E10<=45,"36-45",">45"))) -> 36-45 | G10: Male | H10: Phoenix | I10: marcus.valenzuela@yahoo.com | J10: =MID(I10,FIND("@",I10)+1,100) -> yahoo.com | K10: 694 Graham Prairie Apt. 887, Jimenezfurt, MI 33044 | L10: OID3528 | M10: 45040 | N10: 12:07:00 | O10: PID034 | P10: 275.44 | Q10: 1 | R10: FLAT8 | S10: 8 | T10: 7 | U10: =IF(W10<T10,"Before_time",IF(W10>T10,"Late_Delivery","On_time")) -> Before_time | V10: 63 | W10: =DATEDIF(M10,X10,"D") -> 2 | X10: 45042 | Y10: =YEAR(Table2[[#This Row],[Delivery_Date]]) -> 2023 | Z10: =TEXT(X10,"mmm") -> Apr | AA10: 23:05:41 | AB10: =AD10+V10 -> 316.4048 | AC10: =Table2[[#This Row],[Price]]*Table2[[#This Row],[Quantity]]*Table2[[#This Row],[COUPON %]]/100 -> 22.0352 | AD10: =P10*Q10*(1-S10/100) -> 253.4048 | AE10: =P10*Q10 -> 275.44
A11: CID130 | B11: =CONCATENATE(C11," ", D11," ") -> Debra Rodriguez | C11: Debra | D11: Rodriguez | E11: 48 | F11: =IF(E11<=25,"0-25",IF(E11<=35,"26-35",IF(E11<=45,"36-45",">45"))) -> >45 | G11: Other | H11: Houston | I11: debra.rodriguez@rediffmail.com | J11: =MID(I11,FIND("@",I11)+1,100) -> rediffmail.com | K11: Unit 5964 Box 0721, DPO AP 01840 | L11: OID9634 | M11: 45282 | N11: 13:46:47 | O11: PID033 | P11: 48.45 | Q11: 1 | R11: FLAT15 | S11: 15 | T11: 7 | U11: =IF(W11<T11,"Before_time",IF(W11>T11,"Late_Delivery","On_time")) -> Before_time | V11: 59 | W11: =DATEDIF(M11,X11,"D") -> 5 | X11: 45287 | Y11: =YEAR(Table2[[#This Row],[Delivery_Date]]) -> 2023 | Z11: =TEXT(X11,"mmm") -> Dec | AA11: 19:57:06 | AB11: =AD11+V11 -> 100.1825 | AC11: =Table2[[#This Row],[Price]]*Table2[[#This Row],[Quantity]]*Table2[[#This Row],[COUPON %]]/100 -> 7.2675 | AD11: =P11*Q11*(1-S11/100) -> 41.1825 | AE11: =P11*Q11 -> 48.45
A12: CID115 | B12: =CONCATENATE(C12," ", D12," ") -> Karl Gallagher | C12: Karl | D12: Gallagher | E12: 60 | F12: =IF(E12<=25,"0-25",IF(E12<=35,"26-35",IF(E12<=45,"36-45",">45"))) -> >45 | G12: Other | H12: Phoenix | I12: karl.gallagher@rediffmail.com | J12: =MID(I12,FIND("@",I12)+1,100) -> rediffmail.com | K12: 5016 Snow Mountains Apt. 063, New Seanport, WY 41492 | L12: OID1905 | M12: 45588 | N12: 17:21:43 | O12: PID046 | P12: 363.64 | Q12: 4 | R12: DEL0 | S12: 0 | T12: 2 | U12: =IF(W12<T12,"Before_time",IF(W12>T12,"Late_Delivery","On_time")) -> On_time | V12: 35 | W12: =DATEDIF(M12,X12,"D") -> 2 | X12: 45590 | Y12: =YEAR(Table2[[#This Row],[Delivery_Date]]) -> 2024 | Z12: =TEXT(X12,"mmm") -> Oct | AA12: 08:00:35 | AB12: =AD12+V12 -> 1489.56 | AC12: =Table2[[#This Row],[Price]]*Table2[[#This Row],[Quantity]]*Table2[[#This Row],[COUPON %]]/100 -> 0 | AD12: =P12*Q12*(1-S12/100) -> 1454.56 | AE12: =P12*Q12 -> 1454.56
A13: CID101 | B13: =CONCATENATE(C13," ", D13," ") -> Bobby Forbes | C13: Bobby | D13: Forbes | E13: 20 | F13: =IF(E13<=25,"0-25",IF(E13<=35,"26-35",IF(E13<=45,"36-45",">45"))) -> 0-25 | G13: Male | H13: Los Angeles | I13: bobby.forbes@gmail.com | J13: =MID(I13,FIND("@",I13)+1,100) -> gmail.com | K13: 3079 John Parkway Suite 961, Port Kristaview, MT 91019 | L13: OID3136 | M13: 45498 | N13: 15:09:49 | O13: PID007 | P13: 257.06 | Q13: 3 | R13: DEL0 | S13: 0 | T13: 7 | U13: =IF(W13<T13,"Before_time",IF(W13>T13,"Late_Delivery","On_time")) -> Before_time | V13: 62 | W13: =DATEDIF(M13,X13,"D") -> 1 | X13: 45499 | Y13: =YEAR(Table2[[#This Row],[Delivery_Date]]) -> 2024 | Z13: =TEXT(X13,"mmm") -> Jul | AA13: 22:54:40 | AB13: =AD13+V13 -> 833.18 | AC13: =Table2[[#This Row],[Price]]*Table2[[#This Row],[Quantity]]*Table2[[#This Row],[COUPON %]]/100 -> 0 | AD13: =P13*Q13*(1-S13/100) -> 771.18 | AE13: =P13*Q13 -> 771.18
... A501: CID158 | B501: =CONCATENATE(C501," ", D501," ") -> Angela Evans | C501: Angela | D501: Evans | E501: 52 | F501: =IF(E501<=25,"0-25",IF(E501<=35,"26-35",IF(E501<=45,"36-45",">45"))) -> >45 | G501: Other | H501: Houston | I501: angela.evans@outlook.com | J501: =MID(I501,FIND("@",I501)+1,100) -> outlook.com | K501: 16031 David Mountain Suite 431, Susanborough, PA 01910 | L501: OID6847 | M501: 45501 | N501: 17:02:09 | O501: PID010 | P501: 44.5 | Q501: 4 | R501: DEL0 | S501: 0 | T501: 3 | U501: =IF(W501<T501,"Before_time",IF(W501>T501,"Late_Delivery","On_time")) -> On_time | V501: 45 | W501: =DATEDIF(M501,X501,"D") -> 3 | X501: 45504 | Y501: =YEAR(Table2[[#This Row],[Delivery_Date]]) -> 2024 | Z501: =TEXT(X501,"mmm") -> Jul | AA501: 05:55:32 | AB501: =AD501+V501 -> 223 | AC501: =Table2[[#This Row],[Price]]*Table2[[#This Row],[Quantity]]*Table2[[#This Row],[COUPON %]]/100 -> 0 | AD501: =P501*Q501*(1-S501/100) -> 178 | AE501: =P501*Q501 -> 178

Sheet Project_Questions
B2: 1) Represent the following KPIs inside cards(boxes) in Dashboard
B3: Customer KPIs | G3: Order and Delivery KPIs
B4: a) Find total unique customers | G4: a) Total Orders placed
B5: b) Customer with most orders | G5: b) Average Days to Deliver
B6: c) Customer with highest total order amount | G6: c) Total orders with 0 Delivery Charge
B7: d) Average Customer Age
B10: Product KPIs | J10: .
B11: a) Find total unique products
B12: b) Most ordered product
B13: c) Product which generated highest revenue
B16: Sales KPI
B17: a) Sum Total Sales generated
B18: b) Sum Total Discount offered
B19: c) Total Sales after Discount
B20: d) Avg Sales(exclduing discount)
B22: Q2) Create a new column, Days to deliver and fill it with number of days it took for delivery
B24: Q3) Create a new Amount by using Price and Quantity
B26: Q4) Create a new column for Amount_with_Del_Chrg considering Delivery Charge as well
B28: Q5) Create a new column Discount_Percent and use Coupon_Code to generate it
... B49: 11) Extract email from domain and represent its count on a bar chart

Sheet Sheet1
A1: ANS NO | B1: SOLUTION | C1: FORMULATEXT
A2: 1.a customer KPI | B2: {=SUM(1/COUNTIF(data!A2:A501,data!A2:A501))} -> 100 | C2: =_xlfn.FORMULATEXT(B2) -> {=SUM(1/COUNTIF(data!A2:A501,data!A2:A501))}
A3: 1.b | B3: Row Labels | C3: Count of Order_ID
B4: CID174 | C4: 11
B5: CID162 | C5: 11
B6: Grand Total | C6: 22
A7: 1.c | B7: Row Labels | C7: Sum of Price
B8: CID174 | C8: 3890.76
B9: CID165 | C9: 3262.31
B10: Grand Total | C10: 7153.07
A11: 1.d | B11: =AVERAGE(data!E2:E501) -> 42.124 | C11: =_xlfn.FORMULATEXT(B11) -> =AVERAGE(data!E2:E501)
A14: 1.a order & delvry KPI | B14: =COUNTA(data!L2:L501) -> 500 | C14: =_xlfn.FORMULATEXT(B14) -> =COUNTA(data!L2:L501)
A15: 1.B | B15: =AVERAGE(data!T2:T501) -> 4.08 | C15: =_xlfn.FORMULATEXT(B15) -> =AVERAGE(data!T2:T501)
A16: 1.C | B16: =COUNTIF(data!V2:V501,"=0") -> 0 | C16: =_xlfn.FORMULATEXT(B16) -> =COUNTIF(data!V2:V501,"=0")
A18: 1.A PRODUCT KPI | B18: {=SUM(1/COUNTIF(data!O2:O501,data!O2:O501))} -> 50 | C18: =_xlfn.FORMULATEXT(B18) -> {=SUM(1/COUNTIF(data!O2:O501,data!O2:O501))}
A19: 1.B | B19: PRODUCTS | C19: Count_Order_ID
B20: PID036 | C20: 17
B21: PID046 | C21: 16
B22: Grand Total | C22: 33
A24: 1.C | B24: Row Labels | C24: Sum of REVENUE/TOTAL_AMT
B25: PID027 | C25: 18243.277
B26: PID046 | C26: 15785.612
B27: Grand Total | C27: 34028.89
A30: 1.A SALES KPI | B30: =SUM(data!AE2:AE501) -> 364289.49 | C30: =_xlfn.FORMULATEXT(B30) -> =SUM(data!AE2:AE501)
A31: 1.B | B31: =SUM(data!AC2:AC501) -> 37963.73 | C31: =_xlfn.FORMULATEXT(B31) -> =SUM(data!AC2:AC501)
A32: 1.C | B32: =SUM(data!AD2:AD501) -> 326325.76 | C32: =_xlfn.FORMULATEXT(B32) -> =SUM(data!AD2:AD501)
A33: 1.D | B33: =AVERAGE(data!AE2:AE501) -> 728.57898
A35: 2 | B35: created | C35: =_xlfn.FORMULATEXT(data!W2) -> =DATEDIF(M2,X2,"D")
A37: 3 | B37: created | C37: =_xlfn.FORMULATEXT(data!AE2) -> =P2*Q2
A40: 4 | B40: created | C40: =_xlfn.FORMULATEXT(data!AB2) -> =AD2+V2
A42: 5 | B42: created | C42: =_xlfn.FORMULATEXT(data!W2) -> =DATEDIF(M2,X2,"D")
A44: 6 | B44: created | C44: =_xlfn.FORMULATEXT(data!AB2) -> =AD2+V2
A46: 7 | B46: created | C46: =_xlfn.FORMULATEXT(data!B2) -> =CONCATENATE(C2," ", D2," ")
A48: 8 | B48: created | C48: =_xlfn.FORMULATEXT(data!U2) -> =IF(W2<T2,"Before_time",IF(W2>T2,"Late_Delivery","On_time"))
A51: other charts 1. | B51: Row Labels | C51: Sum of Revnue(Sales-disc)
B52: Jodi Whitney | C52: 12608.679
B53: Lauren Crane | C53: 7925.4583
B54: Mark Summers | C54: 7501.7187
B55: Mary Knight | C55: 7005.5638
B56: Jessica Ruiz | C56: 6570.0678
...
